Workbook

Sheet Stacked Bar
A1: year | B1: fund_balance_bn | C1: claims_paid_bn | D1: premium_proxy_bn | E1: note
A2: 2010 | B2: 295.72 | C2: 7.6 | D2: 69.38 | E2: "premium_proxy_bn=(B2 × mean_premium_rate_pct/100 × 1000"
A3: 2011 | B3: 356.88 | C3: 6.68 | D3: 67.82
A4: 2012 | B4: 425.21 | C4: 6.82 | D4: 74.83
A5: 2013 | B5: 508.06 | C5: 6.82 | D5: 83.85
A6: 2014 | B6: 614.16 | C6: 6.83 | D6: 86.5
A7: 2015 | B7: 725.58 | C7: 6.8 | D7: 70.04
A8: 2016 | B8: 827.89 | C8: 6.8 | D8: 79.72
A9: 2017 | B9: 955.18 | C9: 8.25 | D9: 89.15
A10: 2018 | B10: 1095.23 | C10: 8.25 | D10: 97.79
A11: 2019 | B11: 1201.34 | C11: 8.26 | D11: 110.81
A12: 2020 | B12: 1372.85 | C12: 8.27 | D12: 134.86
A13: 2021 | B13: 1520.86 | C13: 8.27 | D13: 157.44
A14: 2022 | B14: 1762.74 | C14: 8.28 | D14: 182
... A16: 2024 | B16: 2279.36 | C16: 63.21 | D16: 408.44

Sheet IADI Scatter
A1: country | B1: region | C1: avg_coverage_ratio | D1: avg_fund_adequacy
A2: Nigeria | B2: Africa | C2: 1.08 | D2: 0.47
A3: Tanzania | B3: Africa | C3: 0.97 | D3: 0.06
A4: Uganda | B4: Africa | C4: 2.3 | D4: 0.04
A5: USA | B5: Americas | C5: 0 | D5: 0.01
A6: Canada | B6: Americas | C6: 0 | D6: 0.01
A7: Brazil | B7: Americas | C7: 0.01 | D7: 0.03
A8: India | B8: Asia | C8: 0 | D8: 0.02
A9: Indonesia | B9: Asia | C9: 0.04 | D9: 0.04
A10: Malaysia | B10: Asia | C10: 0.01 | D10: 0.01
A11: Philippines | B11: Asia | C11: 0 | D11: 0.09
A12: Vietnam | B12: Asia | C12: 0 | D12: 0.06
A13: Japan | B13: Asia | C13: 0 | D13: 0
... A15: Taiwan | B15: Asia | C15: 0 | D15: 0

Sheet Region Pivot
A1: country | B1: year | C1: coverage_limit_usd | D1: fund_balance_usd | E1: insured_deposits_usd | F1: fund_adequacy_ratio | G1: region
A2: Brazil | B2: 2010 | C2: 39773 | D2: 17045454545 | E2: 375000000000 | F2: 0.0455 | G2: Americas
A3: Brazil | B3: 2011 | C3: 41667 | D3: 20833333333 | E3: 460714285714 | F3: 0.0452 | G3: Americas
A4: Brazil | B4: 2012 | C4: 35897 | D4: 21025641026 | E4: 456923076923 | F4: 0.046 | G4: Americas
A5: Brazil | B5: 2013 | C5: 115741 | D5: 24074074074 | E5: 970185185185 | F5: 0.0248 | G5: Americas
A6: Brazil | B6: 2014 | C6: 106383 | D6: 26382978723 | E6: 1005191489362 | F6: 0.0262 | G6: Americas
A7: Brazil | B7: 2015 | C7: 75075 | D7: 21921921922 | E7: 783843843844 | F7: 0.028 | G7: Americas
A8: Brazil | B8: 2016 | C8: 71633 | D8: 23782234957 | E8: 810085959885 | F8: 0.0294 | G8: Americas
A9: Brazil | B9: 2017 | C9: 78370 | D9: 29153605016 | E9: 936802507837 | F9: 0.0311 | G9: Americas
A10: Brazil | B10: 2018 | C10: 68493 | D10: 28219178082 | E10: 869698630137 | F10: 0.0324 | G10: Americas
A11: Brazil | B11: 2019 | C11: 63452 | D11: 28934010152 | E11: 863908629442 | F11: 0.0335 | G11: Americas
A12: Brazil | B12: 2020 | C12: 46296 | D12: 23148148148 | E12: 711851851852 | F12: 0.0325 | G12: Americas
A13: Brazil | B13: 2021 | C13: 46296 | D13: 25555555556 | E13: 792222222222 | F13: 0.0323 | G13: Americas
... A24: Canada | B24: 2017 | C24: 80000 | D24: 3360000000 | E24: 619200000000 | F24: 0.0054 | G24: Americas
A25: Canada | B25: 2018 | C25: 77200 | D25: 3667000000 | E25: 640760000000 | F25: 0.0057 | G25: =VLOOKUP(A25, 'IADI Scatter'!$A$1:$D$15, 2, FALSE) -> Americas
A26: Canada | B26: 2019 | C26: 75400 | D26: 4033900000 | E26: 669552000000 | F26: 0.006 | G26: =VLOOKUP(A26, 'IADI Scatter'!$A$1:$D$15, 2, FALSE) -> Americas
A27: Canada | B27: 2020 | C27: 74600 | D27: 4476000000 | E27: 723620000000 | F27: 0.0062 | G27: =VLOOKUP(A27, 'IADI Scatter'!$A$1:$D$15, 2, FALSE) -> Americas
A28: Canada | B28: 2021 | C28: 79800 | D28: 5426400000 | E28: 845880000000 | F28: 0.0064 | G28: =VLOOKUP(A28, 'IADI Scatter'!$A$1:$D$15, 2, FALSE) -> Americas
A29: Canada | B29: 2022 | C29: 76900 | D29: 5844400000 | E29: 868970000000 | F29: 0.0067 | G29: =VLOOKUP(A29, 'IADI Scatter'!$A$1:$D$15, 2, FALSE) -> Americas
A30: Canada | B30: 2023 | C30: 74100 | D30: 6150300000 | E30: 881790000000 | F30: 0.007 | G30: =VLOOKUP(A30, 'IADI Scatter'!$A$1:$D$15, 2, FALSE) -> Americas
A31: Canada | B31: 2024 | C31: 73300 | D31: 6670300000 | E31: 909653000000 | F31: 0.0073 | G31: =VLOOKUP(A31, 'IADI Scatter'!$A$1:$D$15, 2, FALSE) -> Americas
A32: India | B32: 2010 | C32: 2188 | D32: 4376367615 | E32: 207877461707 | F32: 0.0211 | G32: =VLOOKUP(A32, 'IADI Scatter'!$A$1:$D$15, 2, FALSE) -> Asia
A33: India | B33: 2011 | C33: 2141 | D33: 5139186296 | E33: 246252676660 | F33: 0.0209 | G33: =VLOOKUP(A33, 'IADI Scatter'!$A$1:$D$15, 2, FALSE) -> Asia
A34: India | B34: 2012 | C34: 1873 | D34: 5243445693 | E34: 258426966292 | F34: 0.0203 | G34: =VLOOKUP(A34, 'IADI Scatter'!$A$1:$D$15, 2, FALSE) -> Asia
A35: India | B35: 2013 | C35: 1664 | D35: 5490848586 | E35: 274542429285 | F35: 0.02 | G35: =VLOOKUP(A35, 'IADI Scatter'!$A$1:$D$15, 2, FALSE) -> Asia
A36: India | B36: 2014 | C36: 1613 | D36: 6290322581 | E36: 314516129032 | F36: 0.02 | G36: =VLOOKUP(A36, 'IADI Scatter'!$A$1:$D$15, 2, FALSE) -> Asia
... A166: Tanzania | B166: 2024 | C166: 2764 | D166: 774050866 | E166: 11979358644 | F166: 0.0646 | G166: =VLOOKUP(A166, 'IADI Scatter'!$A$1:$D$15, 2, FALSE) -> Africa
A167: USA | B167: 2010 | C167: 250000 | D167: -7400000000 | E167: 5400000000000 | F167: -0.0014 | G167: Americas
A168: USA | B168: 2011 | C168: 250000 | D168: 11800000000 | E168: 6300000000000 | F168: 0.0019 | G168: Americas
A169: USA | B169: 2012 | C169: 250000 | D169: 25000000000 | E169: 7400000000000 | F169: 0.0034 | G169: Americas
A170: USA | B170: 2013 | C170: 250000 | D170: 37000000000 | E170: 7000000000000 | F170: 0.0053 | G170: Americas
A171: USA | B171: 2014 | C171: 250000 | D171: 55000000000 | E171: 6700000000000 | F171: 0.0082 | G171: Americas
A172: USA | B172: 2015 | C172: 250000 | D172: 67000000000 | E172: 6400000000000 | F172: 0.0105 | G172: Americas
A173: USA | B173: 2016 | C173: 250000 | D173: 77000000000 | E173: 6800000000000 | F173: 0.0113 | G173: Americas
A174: USA | B174: 2017 | C174: 250000 | D174: 84000000000 | E174: 7100000000000 | F174: 0.0118 | G174: Americas
A175: USA | B175: 2018 | C175: 250000 | D175: 100000000000 | E175: 7338000000000 | F175: 0.0133 | G175: =VLOOKUP(A175, 'IADI Scatter'!$A$1:$D$15, 2, FALSE) -> Americas
A176: USA | B176: 2019 | C176: 250000 | D176: 108000000000 | E176: 7660000000000 | F176: 0.0141 | G176: =VLOOKUP(A176, 'IADI Scatter'!$A$1:$D$15, 2, FALSE) -> Americas
A177: USA | B177: 2020 | C177: 250000 | D177: 117000000000 | E177: 9000000000000 | F177: 0.013 | G177: =VLOOKUP(A177, 'IADI Scatter'!$A$1:$D$15, 2, FALSE) -> Americas
A178: USA | B178: 2021 | C178: 250000 | D178: 124000000000 | E178: 9500000000000 | F178: 0.0131 | G178: =VLOOKUP(A178, 'IADI Scatter'!$A$1:$D$15, 2, FALSE) -> Americas
A179: USA | B179: 2022 | C179: 250000 | D179: 125500000000 | E179: 9900000000000 | F179: 0.0127 | G179: =VLOOKUP(A179, 'IADI Scatter'!$A$1:$D$15, 2, FALSE) -> Americas
...

Sheet Notes
A1: Nigeria's NDIC consistently maintains a fund adequacy ratio well above the IADI 14-country peer average, averaging 0.47 locally versus an IADI peer average of approximately 0.06, driven primarily by a concentrated deposit base and a steadily growing insurance fund that increased from ₦295.7bn in 2010 to ₦2,279.4bn in 2024. However, the 2024 data reveals a structural vulnerability: claims paid spiked from a flat ₦8.3bn range to ₦63.2bn, coinciding with the Naira devaluation shock and the NDIC coverage limit revision, while the IADI-reported fund adequacy ratio diverges sharply from the locally computed figure, signalling that exchange-rate exposure is the primary risk driver. The correlation heatmap confirms that lagged inflation and exchange rate depreciation are negatively correlated with fund adequacy, and the scatter plot positions Nigeria as a high-fund-adequacy, high-coverage outlier among African peers a strength in deposit protection depth, but one that must be interpreted alongside Nigeria's elevated macroeconomic volatility.
